WARNING 2021-01-22 16:25:35,962 log 11140 16904 Not Found: /
WARNING 2021-01-22 16:25:35,963 basehttp 11140 16904 "GET / HTTP/1.1" 404 2032
WARNING 2021-01-22 16:25:36,053 log 11140 16904 Not Found: /favicon.ico
WARNING 2021-01-22 16:25:36,053 basehttp 11140 16904 "GET /favicon.ico HTTP/1.1" 404 2083
ERROR 2021-01-22 17:25:34,849 log 20192 17256 Internal Server Error: /store/book/
Traceback (most recent call last):
  File "C:\Users\Abi Blista\PycharmProjects\pythonProject\venv\lib\site-packages\django\core\handlers\exception.py", line 34, in inner
    response = get_response(request)
  File "C:\Users\Abi Blista\PycharmProjects\pythonProject\venv\lib\site-packages\django\core\handlers\base.py", line 115, in _get_response
    response = self.process_exception_by_middleware(e, request)
  File "C:\Users\Abi Blista\PycharmProjects\pythonProject\venv\lib\site-packages\django\core\handlers\base.py", line 113, in _get_response
    response = wrapped_callback(request, *callback_args, **callback_kwargs)
  File "C:\Users\Abi Blista\PycharmProjects\pythonProject\venv\lib\site-packages\django\views\decorators\csrf.py", line 54, in wrapped_view
    return view_func(*args, **kwargs)
  File "C:\Users\Abi Blista\PycharmProjects\pythonProject\venv\lib\site-packages\rest_framework\viewsets.py", line 117, in view
    handler = getattr(self, action)
AttributeError: 'BookVeiwSet' object has no attribute 'create_Book'
ERROR 2021-01-22 17:25:34,852 basehttp 20192 17256 "GET /store/book/ HTTP/1.1" 500 75163
ERROR 2021-01-22 17:53:38,467 log 11836 21580 Internal Server Error: /store/book/3
Traceback (most recent call last):
  File "C:\Users\Abi Blista\PycharmProjects\pythonProject\venv\lib\site-packages\django\core\handlers\exception.py", line 34, in inner
    response = get_response(request)
  File "C:\Users\Abi Blista\PycharmProjects\pythonProject\venv\lib\site-packages\django\utils\deprecation.py", line 93, in __call__
    response = self.process_request(request)
  File "C:\Users\Abi Blista\PycharmProjects\pythonProject\venv\lib\site-packages\django\middleware\common.py", line 54, in process_request
    path = self.get_full_path_with_slash(request)
  File "C:\Users\Abi Blista\PycharmProjects\pythonProject\venv\lib\site-packages\django\middleware\common.py", line 87, in get_full_path_with_slash
    raise RuntimeError(
RuntimeError: You called this URL via PUT, but the URL doesn't end in a slash and you have APPEND_SLASH set. Django can't redirect to the slash URL while maintaining PUT data. Change your form to point to 127.0.0.1:8000/store/book/3/ (note the trailing slash), or set APPEND_SLASH=False in your Django settings.
ERROR 2021-01-22 17:53:38,468 basehttp 11836 21580 "PUT /store/book/3 HTTP/1.1" 500 68737
