WARNING 2021-01-22 16:25:35,962 log 11140 16904 Not Found: /
WARNING 2021-01-22 16:25:35,963 basehttp 11140 16904 "GET / HTTP/1.1" 404 2032
WARNING 2021-01-22 16:25:36,053 log 11140 16904 Not Found: /favicon.ico
WARNING 2021-01-22 16:25:36,053 basehttp 11140 16904 "GET /favicon.ico HTTP/1.1" 404 2083
ERROR 2021-01-22 17:25:34,849 log 20192 17256 Internal Server Error: /store/book/
Traceback (most recent call last):
  File "C:\Users\Abi Blista\PycharmProjects\pythonProject\venv\lib\site-packages\django\core\handlers\exception.py", line 34, in inner
    response = get_response(request)
  File "C:\Users\Abi Blista\PycharmProjects\pythonProject\venv\lib\site-packages\django\core\handlers\base.py", line 115, in _get_response
    response = self.process_exception_by_middleware(e, request)
  File "C:\Users\Abi Blista\PycharmProjects\pythonProject\venv\lib\site-packages\django\core\handlers\base.py", line 113, in _get_response
    response = wrapped_callback(request, *callback_args, **callback_kwargs)
  File "C:\Users\Abi Blista\PycharmProjects\pythonProject\venv\lib\site-packages\django\views\decorators\csrf.py", line 54, in wrapped_view
    return view_func(*args, **kwargs)
  File "C:\Users\Abi Blista\PycharmProjects\pythonProject\venv\lib\site-packages\rest_framework\viewsets.py", line 117, in view
    handler = getattr(self, action)
AttributeError: 'BookVeiwSet' object has no attribute 'create_Book'
ERROR 2021-01-22 17:25:34,852 basehttp 20192 17256 "GET /store/book/ HTTP/1.1" 500 75163
ERROR 2021-01-22 17:53:38,467 log 11836 21580 Internal Server Error: /store/book/3
Traceback (most recent call last):
  File "C:\Users\Abi Blista\PycharmProjects\pythonProject\venv\lib\site-packages\django\core\handlers\exception.py", line 34, in inner
    response = get_response(request)
  File "C:\Users\Abi Blista\PycharmProjects\pythonProject\venv\lib\site-packages\django\utils\deprecation.py", line 93, in __call__
    response = self.process_request(request)
  File "C:\Users\Abi Blista\PycharmProjects\pythonProject\venv\lib\site-packages\django\middleware\common.py", line 54, in process_request
    path = self.get_full_path_with_slash(request)
  File "C:\Users\Abi Blista\PycharmProjects\pythonProject\venv\lib\site-packages\django\middleware\common.py", line 87, in get_full_path_with_slash
    raise RuntimeError(
RuntimeError: You called this URL via PUT, but the URL doesn't end in a slash and you have APPEND_SLASH set. Django can't redirect to the slash URL while maintaining PUT data. Change your form to point to 127.0.0.1:8000/store/book/3/ (note the trailing slash), or set APPEND_SLASH=False in your Django settings.
ERROR 2021-01-22 17:53:38,468 basehttp 11836 21580 "PUT /store/book/3 HTTP/1.1" 500 68737
WARNING 2021-01-26 19:43:24,472 log 23236 11604 Not Found: /
WARNING 2021-01-26 19:43:24,473 basehttp 23236 11604 "GET / HTTP/1.1" 404 2032
WARNING 2021-01-26 19:43:24,544 log 23236 11604 Not Found: /favicon.ico
WARNING 2021-01-26 19:43:24,545 basehttp 23236 11604 "GET /favicon.ico HTTP/1.1" 404 2083
WARNING 2021-01-26 19:47:19,485 log 27140 18388 Method Not Allowed: /store/book/login/
WARNING 2021-01-26 19:47:19,486 basehttp 27140 18388 "GET /store/book/login/ HTTP/1.1" 405 40
ERROR 2021-01-26 19:47:25,786 log 27140 18388 Internal Server Error: /store/book/login
Traceback (most recent call last):
  File "C:\Users\Abi Blista\AppData\Local\Programs\Python\Python39\lib\site-packages\django\core\handlers\exception.py", line 47, in inner
    response = get_response(request)
  File "C:\Users\Abi Blista\AppData\Local\Programs\Python\Python39\lib\site-packages\django\utils\deprecation.py", line 113, in __call__
    response = self.process_request(request)
  File "C:\Users\Abi Blista\AppData\Local\Programs\Python\Python39\lib\site-packages\django\middleware\common.py", line 54, in process_request
    path = self.get_full_path_with_slash(request)
  File "C:\Users\Abi Blista\AppData\Local\Programs\Python\Python39\lib\site-packages\django\middleware\common.py", line 87, in get_full_path_with_slash
    raise RuntimeError(
RuntimeError: You called this URL via POST, but the URL doesn't end in a slash and you have APPEND_SLASH set. Django can't redirect to the slash URL while maintaining POST data. Change your form to point to 127.0.0.1:8000/store/book/login/ (note the trailing slash), or set APPEND_SLASH=False in your Django settings.
ERROR 2021-01-26 19:47:25,787 basehttp 27140 18388 "POST /store/book/login HTTP/1.1" 500 68307
ERROR 2021-01-26 19:48:00,901 log 27140 20964 Internal Server Error: /store/book/login
Traceback (most recent call last):
  File "C:\Users\Abi Blista\AppData\Local\Programs\Python\Python39\lib\site-packages\django\core\handlers\exception.py", line 47, in inner
    response = get_response(request)
  File "C:\Users\Abi Blista\AppData\Local\Programs\Python\Python39\lib\site-packages\django\utils\deprecation.py", line 113, in __call__
    response = self.process_request(request)
  File "C:\Users\Abi Blista\AppData\Local\Programs\Python\Python39\lib\site-packages\django\middleware\common.py", line 54, in process_request
    path = self.get_full_path_with_slash(request)
  File "C:\Users\Abi Blista\AppData\Local\Programs\Python\Python39\lib\site-packages\django\middleware\common.py", line 87, in get_full_path_with_slash
    raise RuntimeError(
RuntimeError: You called this URL via POST, but the URL doesn't end in a slash and you have APPEND_SLASH set. Django can't redirect to the slash URL while maintaining POST data. Change your form to point to 127.0.0.1:8000/store/book/login/ (note the trailing slash), or set APPEND_SLASH=False in your Django settings.
ERROR 2021-01-26 19:48:00,902 basehttp 27140 20964 "POST /store/book/login HTTP/1.1" 500 68818
ERROR 2021-01-26 19:53:08,234 log 13112 24012 Internal Server Error: /store/book/login/
Traceback (most recent call last):
  File "C:\Users\Abi Blista\AppData\Local\Programs\Python\Python39\lib\site-packages\django\core\handlers\exception.py", line 47, in inner
    response = get_response(request)
  File "C:\Users\Abi Blista\AppData\Local\Programs\Python\Python39\lib\site-packages\django\core\handlers\base.py", line 181, in _get_response
    response = wrapped_callback(request, *callback_args, **callback_kwargs)
  File "C:\Users\Abi Blista\AppData\Local\Programs\Python\Python39\lib\site-packages\django\views\decorators\csrf.py", line 54, in wrapped_view
    return view_func(*args, **kwargs)
  File "C:\Users\Abi Blista\AppData\Local\Programs\Python\Python39\lib\site-packages\rest_framework\viewsets.py", line 125, in view
    return self.dispatch(request, *args, **kwargs)
  File "C:\Users\Abi Blista\AppData\Local\Programs\Python\Python39\lib\site-packages\rest_framework\views.py", line 511, in dispatch
    self.response = self.finalize_response(request, response, *args, **kwargs)
  File "C:\Users\Abi Blista\AppData\Local\Programs\Python\Python39\lib\site-packages\rest_framework\views.py", line 423, in finalize_response
    assert isinstance(response, HttpResponseBase), (
AssertionError: Expected a `Response`, `HttpResponse` or `HttpStreamingResponse` to be returned from the view, but received a `<class 'NoneType'>`
ERROR 2021-01-26 19:53:08,235 basehttp 13112 24012 "POST /store/book/login/ HTTP/1.1" 500 78089
WARNING 2021-01-26 19:56:11,182 log 3076 17168 Not Found: /store/book/login/
WARNING 2021-01-26 19:56:11,183 basehttp 3076 17168 "POST /store/book/login/ HTTP/1.1" 404 31
WARNING 2021-01-26 19:57:31,974 log 3076 17168 Not Found: /store/book/login/
WARNING 2021-01-26 19:57:31,974 basehttp 3076 17168 "POST /store/book/login/ HTTP/1.1" 404 31
WARNING 2021-01-26 19:58:02,170 log 3076 17168 Not Found: /store/book/login/
WARNING 2021-01-26 19:58:02,171 basehttp 3076 17168 "POST /store/book/login/ HTTP/1.1" 404 42
WARNING 2021-02-02 18:31:40,951 log 19324 14224 Not Found: /
WARNING 2021-02-02 18:31:40,951 basehttp 19324 14224 "GET / HTTP/1.1" 404 2032
WARNING 2021-02-02 18:31:41,003 log 19324 14224 Not Found: /favicon.ico
WARNING 2021-02-02 18:31:41,004 basehttp 19324 14224 "GET /favicon.ico HTTP/1.1" 404 2083
ERROR 2021-02-02 18:36:19,713 exception 19324 2132 Invalid HTTP_HOST header: '2aa3a031474a.ngrok.io'. You may need to add '2aa3a031474a.ngrok.io' to ALLOWED_HOSTS.
WARNING 2021-02-02 18:36:19,773 log 19324 2132 Bad Request: /
WARNING 2021-02-02 18:36:19,774 basehttp 19324 2132 "GET / HTTP/1.1" 400 68022
ERROR 2021-02-02 18:36:19,941 exception 19324 9796 Invalid HTTP_HOST header: '2aa3a031474a.ngrok.io'. You may need to add '2aa3a031474a.ngrok.io' to ALLOWED_HOSTS.
WARNING 2021-02-02 18:36:19,963 log 19324 9796 Bad Request: /favicon.ico
WARNING 2021-02-02 18:36:19,964 basehttp 19324 9796 "GET /favicon.ico HTTP/1.1" 400 68521
ERROR 2021-02-02 18:36:19,983 exception 19324 13924 Invalid HTTP_HOST header: '2aa3a031474a.ngrok.io'. You may need to add '2aa3a031474a.ngrok.io' to ALLOWED_HOSTS.
WARNING 2021-02-02 18:36:20,004 log 19324 13924 Bad Request: /
WARNING 2021-02-02 18:36:20,005 basehttp 19324 13924 "GET / HTTP/1.1" 400 68612
ERROR 2021-02-02 18:36:21,772 exception 19324 8448 Invalid HTTP_HOST header: '2aa3a031474a.ngrok.io'. You may need to add '2aa3a031474a.ngrok.io' to ALLOWED_HOSTS.
WARNING 2021-02-02 18:36:21,787 log 19324 8448 Bad Request: /favicon.ico
WARNING 2021-02-02 18:36:21,788 basehttp 19324 8448 "GET /favicon.ico HTTP/1.1" 400 68521
ERROR 2021-02-02 18:36:33,929 exception 19324 19296 Invalid HTTP_HOST header: '2aa3a031474a.ngrok.io'. You may need to add '2aa3a031474a.ngrok.io' to ALLOWED_HOSTS.
WARNING 2021-02-02 18:36:33,947 log 19324 19296 Bad Request: /store/book/
WARNING 2021-02-02 18:36:33,947 basehttp 19324 19296 "GET /store/book/ HTTP/1.1" 400 68582
ERROR 2021-02-02 18:36:35,099 exception 19324 17680 Invalid HTTP_HOST header: '2aa3a031474a.ngrok.io'. You may need to add '2aa3a031474a.ngrok.io' to ALLOWED_HOSTS.
WARNING 2021-02-02 18:36:35,120 log 19324 17680 Bad Request: /favicon.ico
WARNING 2021-02-02 18:36:35,121 basehttp 19324 17680 "GET /favicon.ico HTTP/1.1" 400 68532
ERROR 2021-02-02 18:37:28,594 exception 18252 5920 Invalid HTTP_HOST header: '2aa3a031474a.ngrok.io'. You may need to add '2aa3a031474a.ngrok.io' to ALLOWED_HOSTS.
WARNING 2021-02-02 18:37:28,628 log 18252 5920 Bad Request: /store/book/
WARNING 2021-02-02 18:37:28,629 basehttp 18252 5920 "GET /store/book/ HTTP/1.1" 400 68280
ERROR 2021-02-02 18:37:29,381 exception 18252 15380 Invalid HTTP_HOST header: '2aa3a031474a.ngrok.io'. You may need to add '2aa3a031474a.ngrok.io' to ALLOWED_HOSTS.
WARNING 2021-02-02 18:37:29,400 log 18252 15380 Bad Request: /store/book/
WARNING 2021-02-02 18:37:29,400 basehttp 18252 15380 "GET /store/book/ HTTP/1.1" 400 68744
ERROR 2021-02-02 18:37:30,545 exception 18252 12460 Invalid HTTP_HOST header: '2aa3a031474a.ngrok.io'. You may need to add '2aa3a031474a.ngrok.io' to ALLOWED_HOSTS.
WARNING 2021-02-02 18:37:30,562 log 18252 12460 Bad Request: /favicon.ico
WARNING 2021-02-02 18:37:30,562 basehttp 18252 12460 "GET /favicon.ico HTTP/1.1" 400 68093
ERROR 2021-02-02 18:38:25,661 exception 16364 20012 Invalid HTTP_HOST header: '2aa3a031474a.ngrok.io'. You may need to add '2aa3a031474a.ngrok.io' to ALLOWED_HOSTS.
WARNING 2021-02-02 18:38:25,699 log 16364 20012 Bad Request: /store/book/
WARNING 2021-02-02 18:38:25,699 basehttp 16364 20012 "GET /store/book/ HTTP/1.1" 400 68881
ERROR 2021-02-02 18:38:26,860 exception 16364 12940 Invalid HTTP_HOST header: '2aa3a031474a.ngrok.io'. You may need to add '2aa3a031474a.ngrok.io' to ALLOWED_HOSTS.
WARNING 2021-02-02 18:38:26,894 log 16364 12940 Bad Request: /favicon.ico
WARNING 2021-02-02 18:38:26,895 basehttp 16364 12940 "GET /favicon.ico HTTP/1.1" 400 68358
ERROR 2021-02-02 18:40:50,122 exception 16364 21868 Invalid HTTP_HOST header: '5a0cf98d48b7.ngrok.io'. You may need to add '5a0cf98d48b7.ngrok.io' to ALLOWED_HOSTS.
WARNING 2021-02-02 18:40:50,144 log 16364 21868 Bad Request: /store/book/
WARNING 2021-02-02 18:40:50,145 basehttp 16364 21868 "GET /store/book/ HTTP/1.1" 400 68143
ERROR 2021-02-02 18:40:50,349 exception 16364 11648 Invalid HTTP_HOST header: '5a0cf98d48b7.ngrok.io'. You may need to add '5a0cf98d48b7.ngrok.io' to ALLOWED_HOSTS.
WARNING 2021-02-02 18:40:50,365 log 16364 11648 Bad Request: /favicon.ico
WARNING 2021-02-02 18:40:50,365 basehttp 16364 11648 "GET /favicon.ico HTTP/1.1" 400 68093
ERROR 2021-02-02 18:40:50,403 exception 16364 19340 Invalid HTTP_HOST header: '5a0cf98d48b7.ngrok.io'. You may need to add '5a0cf98d48b7.ngrok.io' to ALLOWED_HOSTS.
WARNING 2021-02-02 18:40:50,420 log 16364 19340 Bad Request: /store/book/
WARNING 2021-02-02 18:40:50,420 basehttp 16364 19340 "GET /store/book/ HTTP/1.1" 400 68744
ERROR 2021-02-02 18:40:52,420 exception 16364 3588 Invalid HTTP_HOST header: '5a0cf98d48b7.ngrok.io'. You may need to add '5a0cf98d48b7.ngrok.io' to ALLOWED_HOSTS.
WARNING 2021-02-02 18:40:52,436 log 16364 3588 Bad Request: /favicon.ico
WARNING 2021-02-02 18:40:52,437 basehttp 16364 3588 "GET /favicon.ico HTTP/1.1" 400 68093
WARNING 2021-02-02 18:41:12,734 log 16364 12176 Not Found: /
WARNING 2021-02-02 18:41:12,734 basehttp 16364 12176 "GET / HTTP/1.1" 404 2032
ERROR 2021-02-02 18:41:27,543 exception 16364 17068 Invalid HTTP_HOST header: '5a0cf98d48b7.ngrok.io'. You may need to add '5a0cf98d48b7.ngrok.io' to ALLOWED_HOSTS.
WARNING 2021-02-02 18:41:27,561 log 16364 17068 Bad Request: /store/book/
WARNING 2021-02-02 18:41:27,561 basehttp 16364 17068 "GET /store/book/ HTTP/1.1" 400 68719
ERROR 2021-02-02 18:41:29,000 exception 16364 3844 Invalid HTTP_HOST header: '5a0cf98d48b7.ngrok.io'. You may need to add '5a0cf98d48b7.ngrok.io' to ALLOWED_HOSTS.
WARNING 2021-02-02 18:41:29,067 log 16364 3844 Bad Request: /favicon.ico
WARNING 2021-02-02 18:41:29,068 basehttp 16364 3844 "GET /favicon.ico HTTP/1.1" 400 68093
ERROR 2021-02-02 18:42:20,257 exception 12116 1872 Invalid HTTP_HOST header: '5a0cf98d48b7.ngrok.io'. You may need to add '5a0cf98d48b7.ngrok.io' to ALLOWED_HOSTS.
WARNING 2021-02-02 18:42:20,280 log 12116 1872 Bad Request: /store/book/
WARNING 2021-02-02 18:42:20,280 basehttp 12116 1872 "GET /store/book/ HTTP/1.1" 400 68280
ERROR 2021-02-02 18:42:20,781 exception 12116 20292 Invalid HTTP_HOST header: '5a0cf98d48b7.ngrok.io'. You may need to add '5a0cf98d48b7.ngrok.io' to ALLOWED_HOSTS.
WARNING 2021-02-02 18:42:20,797 log 12116 20292 Bad Request: /store/book/
WARNING 2021-02-02 18:42:20,797 basehttp 12116 20292 "GET /store/book/ HTTP/1.1" 400 68744
ERROR 2021-02-02 18:42:22,258 exception 12116 14596 Invalid HTTP_HOST header: '5a0cf98d48b7.ngrok.io'. You may need to add '5a0cf98d48b7.ngrok.io' to ALLOWED_HOSTS.
WARNING 2021-02-02 18:42:22,286 log 12116 14596 Bad Request: /favicon.ico
WARNING 2021-02-02 18:42:22,286 basehttp 12116 14596 "GET /favicon.ico HTTP/1.1" 400 68093
WARNING 2021-02-02 18:46:28,495 log 15960 13416 Not Found: /
WARNING 2021-02-02 18:46:28,496 basehttp 15960 13416 "GET / HTTP/1.1" 404 2032
WARNING 2021-02-02 18:47:29,738 log 17088 8092 Not Found: /favicon.ico
WARNING 2021-02-02 18:47:29,739 basehttp 17088 8092 "GET /favicon.ico HTTP/1.1" 404 2090
WARNING 2021-02-02 18:48:36,541 log 17088 3224 Not Found: /robots.txt
WARNING 2021-02-02 18:48:36,541 basehttp 17088 3224 "GET /robots.txt HTTP/1.1" 404 2087
WARNING 2021-02-02 18:48:40,061 log 17088 22324 Not Found: /favicon.ico
WARNING 2021-02-02 18:48:40,061 basehttp 17088 22324 "GET /favicon.ico HTTP/1.1" 404 2090
WARNING 2021-02-02 18:48:54,435 log 17088 21580 Not Found: /favicon.ico
WARNING 2021-02-02 18:48:54,436 basehttp 17088 21580 "GET /favicon.ico HTTP/1.1" 404 2090
WARNING 2021-02-02 18:49:02,266 log 17088 5504 Not Found: /favicon.ico
WARNING 2021-02-02 18:49:02,266 basehttp 17088 5504 "GET /favicon.ico HTTP/1.1" 404 2090
WARNING 2021-02-10 02:59:54,236 log 18832 17992 Not Found: /
WARNING 2021-02-10 02:59:54,237 basehttp 18832 17992 "GET / HTTP/1.1" 404 2032
WARNING 2021-02-10 02:59:54,334 log 18832 17992 Not Found: /favicon.ico
WARNING 2021-02-10 02:59:54,334 basehttp 18832 17992 "GET /favicon.ico HTTP/1.1" 404 2083
WARNING 2021-02-10 03:00:09,458 log 18832 17992 Not Found: /
WARNING 2021-02-10 03:00:09,458 basehttp 18832 17992 "GET / HTTP/1.1" 404 2032
WARNING 2021-02-10 03:00:18,095 log 18832 17992 Not Found: /book/store/
WARNING 2021-02-10 03:00:18,096 basehttp 18832 17992 "GET /book/store/ HTTP/1.1" 404 2083
ERROR 2021-02-10 03:18:53,997 log 13984 17296 Internal Server Error: /store/user/
Traceback (most recent call last):
  File "C:\Users\Abi Blista\AppData\Local\Programs\Python\Python39\lib\site-packages\django\core\handlers\exception.py", line 47, in inner
    response = get_response(request)
  File "C:\Users\Abi Blista\AppData\Local\Programs\Python\Python39\lib\site-packages\django\core\handlers\base.py", line 181, in _get_response
    response = wrapped_callback(request, *callback_args, **callback_kwargs)
  File "C:\Users\Abi Blista\AppData\Local\Programs\Python\Python39\lib\site-packages\django\views\decorators\csrf.py", line 54, in wrapped_view
    return view_func(*args, **kwargs)
  File "C:\Users\Abi Blista\AppData\Local\Programs\Python\Python39\lib\site-packages\rest_framework\viewsets.py", line 117, in view
    handler = getattr(self, action)
AttributeError: 'BookVeiwSet' object has no attribute 'list_User'
ERROR 2021-02-10 03:18:53,999 basehttp 13984 17296 "POST /store/user/?username=ImUser&usertype=reader&password=ImUser&country=canada&mailid=ImUser@ca.com&contact=1001000 HTTP/1.1" 500 69715
ERROR 2021-02-10 03:20:06,161 log 9636 19972 Internal Server Error: /store/user/
Traceback (most recent call last):
  File "C:\Users\Abi Blista\AppData\Local\Programs\Python\Python39\lib\site-packages\django\core\handlers\exception.py", line 47, in inner
    response = get_response(request)
  File "C:\Users\Abi Blista\AppData\Local\Programs\Python\Python39\lib\site-packages\django\core\handlers\base.py", line 181, in _get_response
    response = wrapped_callback(request, *callback_args, **callback_kwargs)
  File "C:\Users\Abi Blista\AppData\Local\Programs\Python\Python39\lib\site-packages\django\views\decorators\csrf.py", line 54, in wrapped_view
    return view_func(*args, **kwargs)
  File "C:\Users\Abi Blista\AppData\Local\Programs\Python\Python39\lib\site-packages\rest_framework\viewsets.py", line 117, in view
    handler = getattr(self, action)
AttributeError: 'UserVeiwSet' object has no attribute 'list_User'
ERROR 2021-02-10 03:20:06,162 basehttp 9636 19972 "POST /store/user/?username=ImUser&usertype=reader&password=ImUser&country=canada&mailid=ImUser@ca.com&contact=1001000 HTTP/1.1" 500 69715
WARNING 2021-02-10 03:25:45,970 log 7852 19996 Not Found: /
WARNING 2021-02-10 03:25:45,970 basehttp 7852 19996 "GET / HTTP/1.1" 404 2032
WARNING 2021-02-10 03:39:57,939 log 10848 5680 Not Found: /store/login/
WARNING 2021-02-10 03:39:57,940 basehttp 10848 5680 "POST /store/login/ HTTP/1.1" 404 2827
WARNING 2021-02-10 03:41:04,728 log 10848 5680 Not Found: /store/book/login/
WARNING 2021-02-10 03:41:04,728 basehttp 10848 5680 "POST /store/book/login/ HTTP/1.1" 404 31
WARNING 2021-02-14 16:50:33,582 log 17108 11188 Not Found: /
WARNING 2021-02-14 16:50:33,582 basehttp 17108 11188 "GET / HTTP/1.1" 404 2032
WARNING 2021-02-14 16:50:33,631 log 17108 11188 Not Found: /favicon.ico
WARNING 2021-02-14 16:50:33,631 basehttp 17108 11188 "GET /favicon.ico HTTP/1.1" 404 2083
WARNING 2021-02-16 00:33:03,309 log 18964 5484 Not Found: /
WARNING 2021-02-16 00:33:03,309 basehttp 18964 5484 "GET / HTTP/1.1" 404 2032
WARNING 2021-02-16 00:33:03,370 log 18964 5484 Not Found: /favicon.ico
WARNING 2021-02-16 00:33:03,370 basehttp 18964 5484 "GET /favicon.ico HTTP/1.1" 404 2083
WARNING 2021-02-16 01:18:08,366 log 18480 19060 Not Found: /
WARNING 2021-02-16 01:18:08,367 basehttp 18480 19060 "GET / HTTP/1.1" 404 2032
WARNING 2021-02-16 02:10:17,578 log 10824 17480 Not Found: /favicon.ico
WARNING 2021-02-16 02:10:17,579 basehttp 10824 17480 "GET /favicon.ico HTTP/1.1" 404 2083
WARNING 2021-02-16 03:34:04,245 log 22052 23960 Not Found: /store/login
WARNING 2021-02-16 03:34:04,245 basehttp 22052 23960 "POST /store/login HTTP/1.1" 404 2824
WARNING 2021-02-16 03:34:19,341 log 22052 23960 Not Found: /store/login/
WARNING 2021-02-16 03:34:19,341 basehttp 22052 23960 "POST /store/login/ HTTP/1.1" 404 2827
WARNING 2021-02-16 03:39:52,227 log 16352 11420 Not Found: /store/book/login/
WARNING 2021-02-16 03:39:52,227 basehttp 16352 11420 "POST /store/book/login/ HTTP/1.1" 404 42
WARNING 2021-02-16 03:46:43,704 log 12496 20996 Unauthorized: /store/book/
WARNING 2021-02-16 03:46:43,704 basehttp 12496 20996 "GET /store/book/ HTTP/1.1" 401 58
WARNING 2021-02-16 03:48:59,205 log 12496 20996 Unauthorized: /store/book/
WARNING 2021-02-16 03:48:59,205 basehttp 12496 20996 "GET /store/book/ HTTP/1.1" 401 58
WARNING 2021-02-16 03:49:03,639 log 12496 20996 Unauthorized: /store/book/
WARNING 2021-02-16 03:49:03,640 basehttp 12496 20996 "GET /store/book/ HTTP/1.1" 401 58
WARNING 2021-02-16 03:54:16,858 log 12496 20996 Unauthorized: /store/book/
WARNING 2021-02-16 03:54:16,858 basehttp 12496 20996 "GET /store/book/ HTTP/1.1" 401 58
WARNING 2021-02-16 04:54:40,286 log 17256 12912 Unauthorized: /store/book/
WARNING 2021-02-16 04:54:40,286 basehttp 17256 12912 "GET /store/book/ HTTP/1.1" 401 5090
WARNING 2021-02-16 05:03:12,997 log 21028 24128 Not Found: /store/book/activate_user/25/
WARNING 2021-02-16 05:03:12,998 basehttp 21028 24128 "GET /store/book/activate_user/25/ HTTP/1.1" 404 3175
WARNING 2021-02-16 05:10:29,936 log 6988 21512 Unauthorized: /store/book/
WARNING 2021-02-16 05:10:29,936 basehttp 6988 21512 "GET /store/book/ HTTP/1.1" 401 5090
WARNING 2021-02-16 05:13:36,033 log 24240 23920 Unauthorized: /store/book/
WARNING 2021-02-16 05:13:36,033 basehttp 24240 23920 "GET /store/book/ HTTP/1.1" 401 5090
WARNING 2021-02-16 05:13:38,292 log 24240 23920 Unauthorized: /store/book/
WARNING 2021-02-16 05:13:38,292 basehttp 24240 23920 "GET /store/book/ HTTP/1.1" 401 5090
ERROR 2021-02-16 05:13:50,167 log 24240 23920 Internal Server Error: /store/activate_user/26/
Traceback (most recent call last):
  File "C:\Users\Abi Blista\AppData\Local\Programs\Python\Python39\lib\site-packages\django\core\handlers\exception.py", line 47, in inner
    response = get_response(request)
  File "C:\Users\Abi Blista\AppData\Local\Programs\Python\Python39\lib\site-packages\django\core\handlers\base.py", line 181, in _get_response
    response = wrapped_callback(request, *callback_args, **callback_kwargs)
  File "C:\Users\Abi Blista\AppData\Local\Programs\Python\Python39\lib\site-packages\django\views\decorators\csrf.py", line 54, in wrapped_view
    return view_func(*args, **kwargs)
  File "C:\Users\Abi Blista\AppData\Local\Programs\Python\Python39\lib\site-packages\django\views\generic\base.py", line 70, in view
    return self.dispatch(request, *args, **kwargs)
  File "C:\Users\Abi Blista\AppData\Local\Programs\Python\Python39\lib\site-packages\rest_framework\views.py", line 509, in dispatch
    response = self.handle_exception(exc)
  File "C:\Users\Abi Blista\AppData\Local\Programs\Python\Python39\lib\site-packages\rest_framework\views.py", line 469, in handle_exception
    self.raise_uncaught_exception(exc)
  File "C:\Users\Abi Blista\AppData\Local\Programs\Python\Python39\lib\site-packages\rest_framework\views.py", line 480, in raise_uncaught_exception
    raise exc
  File "C:\Users\Abi Blista\AppData\Local\Programs\Python\Python39\lib\site-packages\rest_framework\views.py", line 506, in dispatch
    response = handler(request, *args, **kwargs)
  File "C:\Users\Abi Blista\AppData\Local\Programs\Python\Python39\lib\site-packages\rest_framework\decorators.py", line 50, in handler
    return func(*args, **kwargs)
TypeError: activate_User() missing 1 required positional argument: 'request'
ERROR 2021-02-16 05:13:50,169 basehttp 24240 23920 "GET /store/activate_user/26/ HTTP/1.1" 500 93075
ERROR 2021-02-16 05:16:33,731 log 17712 21976 Internal Server Error: /store/activate_user/26/
Traceback (most recent call last):
  File "C:\Users\Abi Blista\AppData\Local\Programs\Python\Python39\lib\site-packages\django\core\handlers\exception.py", line 47, in inner
    response = get_response(request)
  File "C:\Users\Abi Blista\AppData\Local\Programs\Python\Python39\lib\site-packages\django\core\handlers\base.py", line 181, in _get_response
    response = wrapped_callback(request, *callback_args, **callback_kwargs)
  File "C:\Users\Abi Blista\AppData\Local\Programs\Python\Python39\lib\site-packages\django\views\decorators\csrf.py", line 54, in wrapped_view
    return view_func(*args, **kwargs)
  File "C:\Users\Abi Blista\AppData\Local\Programs\Python\Python39\lib\site-packages\django\views\generic\base.py", line 70, in view
    return self.dispatch(request, *args, **kwargs)
  File "C:\Users\Abi Blista\AppData\Local\Programs\Python\Python39\lib\site-packages\rest_framework\views.py", line 509, in dispatch
    response = self.handle_exception(exc)
  File "C:\Users\Abi Blista\AppData\Local\Programs\Python\Python39\lib\site-packages\rest_framework\views.py", line 469, in handle_exception
    self.raise_uncaught_exception(exc)
  File "C:\Users\Abi Blista\AppData\Local\Programs\Python\Python39\lib\site-packages\rest_framework\views.py", line 480, in raise_uncaught_exception
    raise exc
  File "C:\Users\Abi Blista\AppData\Local\Programs\Python\Python39\lib\site-packages\rest_framework\views.py", line 506, in dispatch
    response = handler(request, *args, **kwargs)
  File "C:\Users\Abi Blista\AppData\Local\Programs\Python\Python39\lib\site-packages\rest_framework\decorators.py", line 50, in handler
    return func(*args, **kwargs)
TypeError: activate_User() got an unexpected keyword argument 'pk'
ERROR 2021-02-16 05:16:33,732 basehttp 17712 21976 "GET /store/activate_user/26/ HTTP/1.1" 500 93015
WARNING 2021-02-16 05:18:44,052 log 15924 23796 Method Not Allowed: /store/activate_user/
WARNING 2021-02-16 05:18:44,053 basehttp 15924 23796 "POST /store/activate_user/?pk=26/ HTTP/1.1" 405 41
WARNING 2021-02-16 05:20:16,156 log 20184 20676 Unauthorized: /store/book/
WARNING 2021-02-16 05:20:16,157 basehttp 20184 20676 "GET /store/book/ HTTP/1.1" 401 58
WARNING 2021-02-16 05:28:00,322 log 20628 5896 Unauthorized: /store/book/
WARNING 2021-02-16 05:28:00,323 basehttp 20628 5896 "GET /store/book/ HTTP/1.1" 401 58
WARNING 2021-02-16 05:28:03,024 log 20628 5896 Unauthorized: /store/book/
WARNING 2021-02-16 05:28:03,024 basehttp 20628 5896 "GET /store/book/ HTTP/1.1" 401 58
WARNING 2021-02-16 05:28:05,531 log 20628 5896 Unauthorized: /store/book/
WARNING 2021-02-16 05:28:05,531 basehttp 20628 5896 "GET /store/book/ HTTP/1.1" 401 58
WARNING 2021-02-16 05:29:28,350 log 20628 5896 Unauthorized: /store/book/
WARNING 2021-02-16 05:29:28,350 basehttp 20628 5896 "GET /store/book/ HTTP/1.1" 401 58
WARNING 2021-02-16 05:29:59,450 log 20628 5896 Unauthorized: /store/book/
WARNING 2021-02-16 05:29:59,451 basehttp 20628 5896 "GET /store/book/ HTTP/1.1" 401 58
ERROR 2021-02-16 14:13:58,944 log 13764 3696 Internal Server Error: /store/activate_user/
Traceback (most recent call last):
  File "C:\Users\Abi Blista\AppData\Local\Programs\Python\Python39\lib\site-packages\django\core\handlers\exception.py", line 47, in inner
    response = get_response(request)
  File "C:\Users\Abi Blista\AppData\Local\Programs\Python\Python39\lib\site-packages\django\core\handlers\base.py", line 204, in _get_response
    response = response.render()
  File "C:\Users\Abi Blista\AppData\Local\Programs\Python\Python39\lib\site-packages\django\template\response.py", line 105, in render
    self.content = self.rendered_content
  File "C:\Users\Abi Blista\AppData\Local\Programs\Python\Python39\lib\site-packages\rest_framework\response.py", line 55, in rendered_content
    assert renderer, ".accepted_renderer not set on Response"
AssertionError: .accepted_renderer not set on Response
ERROR 2021-02-16 14:13:58,945 basehttp 13764 3696 "GET /store/activate_user/?pk=26 HTTP/1.1" 500 67908
ERROR 2021-02-16 14:20:01,473 log 6036 8704 Internal Server Error: /store/activate_user/
Traceback (most recent call last):
  File "C:\Users\Abi Blista\AppData\Local\Programs\Python\Python39\lib\site-packages\django\core\handlers\exception.py", line 47, in inner
    response = get_response(request)
  File "C:\Users\Abi Blista\AppData\Local\Programs\Python\Python39\lib\site-packages\django\core\handlers\base.py", line 204, in _get_response
    response = response.render()
  File "C:\Users\Abi Blista\AppData\Local\Programs\Python\Python39\lib\site-packages\django\template\response.py", line 105, in render
    self.content = self.rendered_content
  File "C:\Users\Abi Blista\AppData\Local\Programs\Python\Python39\lib\site-packages\rest_framework\response.py", line 55, in rendered_content
    assert renderer, ".accepted_renderer not set on Response"
AssertionError: .accepted_renderer not set on Response
ERROR 2021-02-16 14:20:01,474 basehttp 6036 8704 "GET /store/activate_user/?pk=26 HTTP/1.1" 500 67908
WARNING 2021-02-16 14:20:40,263 log 22656 13716 Unauthorized: /store/book/
WARNING 2021-02-16 14:20:40,263 basehttp 22656 13716 "GET /store/book/ HTTP/1.1" 401 58
WARNING 2021-02-16 14:22:35,305 log 4292 3340 Unauthorized: /store/book/
WARNING 2021-02-16 14:22:35,305 basehttp 4292 3340 "GET /store/book/ HTTP/1.1" 401 58
WARNING 2021-02-16 14:22:36,589 log 4292 3340 Unauthorized: /store/book/
WARNING 2021-02-16 14:22:36,590 basehttp 4292 3340 "GET /store/book/ HTTP/1.1" 401 58
WARNING 2021-02-16 14:22:39,860 log 4292 3340 Unauthorized: /store/book/
WARNING 2021-02-16 14:22:39,860 basehttp 4292 3340 "GET /store/book/ HTTP/1.1" 401 58
WARNING 2021-02-16 14:24:14,802 log 15724 24368 Unauthorized: /store/book/
WARNING 2021-02-16 14:24:14,803 basehttp 15724 24368 "GET /store/book/ HTTP/1.1" 401 58
WARNING 2021-02-16 15:00:10,490 log 15884 19488 Unauthorized: /store/book/
WARNING 2021-02-16 15:00:10,490 basehttp 15884 19488 "GET /store/book/ HTTP/1.1" 401 5090
WARNING 2021-02-16 15:00:11,296 log 15884 20728 Not Found: /favicon.ico
WARNING 2021-02-16 15:00:11,297 basehttp 15884 20728 "GET /favicon.ico HTTP/1.1" 404 2196
WARNING 2021-02-16 15:00:30,742 log 15884 19748 Not Found: /store/activate_user/26/
WARNING 2021-02-16 15:00:30,742 basehttp 15884 19748 "GET /store/activate_user/26/ HTTP/1.1" 404 3142
WARNING 2021-02-16 15:01:01,298 log 15884 21444 Unauthorized: /store/book/
WARNING 2021-02-16 15:01:01,298 basehttp 15884 21444 "GET /store/book/ HTTP/1.1" 401 5090
WARNING 2021-02-16 15:01:14,222 log 15884 21444 Unauthorized: /store/book/
WARNING 2021-02-16 15:01:14,222 basehttp 15884 21444 "GET /store/book/ HTTP/1.1" 401 5090
ERROR 2021-02-16 15:25:23,910 log 18140 12320 Internal Server Error: /store/user
Traceback (most recent call last):
  File "C:\Users\Abi Blista\AppData\Local\Programs\Python\Python39\lib\site-packages\django\core\handlers\exception.py", line 47, in inner
    response = get_response(request)
  File "C:\Users\Abi Blista\AppData\Local\Programs\Python\Python39\lib\site-packages\django\utils\deprecation.py", line 113, in __call__
    response = self.process_request(request)
  File "C:\Users\Abi Blista\AppData\Local\Programs\Python\Python39\lib\site-packages\django\middleware\common.py", line 54, in process_request
    path = self.get_full_path_with_slash(request)
  File "C:\Users\Abi Blista\AppData\Local\Programs\Python\Python39\lib\site-packages\django\middleware\common.py", line 87, in get_full_path_with_slash
    raise RuntimeError(
RuntimeError: You called this URL via POST, but the URL doesn't end in a slash and you have APPEND_SLASH set. Django can't redirect to the slash URL while maintaining POST data. Change your form to point to 127.0.0.1:8000/store/user/ (note the trailing slash), or set APPEND_SLASH=False in your Django settings.
ERROR 2021-02-16 15:25:23,911 basehttp 18140 12320 "POST /store/user HTTP/1.1" 500 69742
WARNING 2021-02-16 15:40:27,286 log 19856 5468 Not Found: /store/book/login/
WARNING 2021-02-16 15:40:27,286 basehttp 19856 5468 "POST /store/book/login/ HTTP/1.1" 404 49
WARNING 2021-02-16 15:41:01,441 log 19856 20540 Unauthorized: /store/book/
WARNING 2021-02-16 15:41:01,442 basehttp 19856 20540 "GET /store/book/ HTTP/1.1" 401 5090
ERROR 2021-02-16 15:43:24,552 log 19856 5468 Internal Server Error: /store/user
Traceback (most recent call last):
  File "C:\Users\Abi Blista\AppData\Local\Programs\Python\Python39\lib\site-packages\django\core\handlers\exception.py", line 47, in inner
    response = get_response(request)
  File "C:\Users\Abi Blista\AppData\Local\Programs\Python\Python39\lib\site-packages\django\utils\deprecation.py", line 113, in __call__
    response = self.process_request(request)
  File "C:\Users\Abi Blista\AppData\Local\Programs\Python\Python39\lib\site-packages\django\middleware\common.py", line 54, in process_request
    path = self.get_full_path_with_slash(request)
  File "C:\Users\Abi Blista\AppData\Local\Programs\Python\Python39\lib\site-packages\django\middleware\common.py", line 87, in get_full_path_with_slash
    raise RuntimeError(
RuntimeError: You called this URL via POST, but the URL doesn't end in a slash and you have APPEND_SLASH set. Django can't redirect to the slash URL while maintaining POST data. Change your form to point to 127.0.0.1:8000/store/user/ (note the trailing slash), or set APPEND_SLASH=False in your Django settings.
ERROR 2021-02-16 15:43:24,553 basehttp 19856 5468 "POST /store/user HTTP/1.1" 500 69879
WARNING 2021-02-16 15:43:50,152 log 19856 10224 Not Found: /store/book/login/
WARNING 2021-02-16 15:43:50,153 basehttp 19856 10224 "POST /store/book/login/ HTTP/1.1" 404 49
WARNING 2021-02-16 17:06:03,578 log 1928 19116 Not Found: /
WARNING 2021-02-16 17:06:03,578 basehttp 1928 19116 "GET / HTTP/1.1" 404 2145
WARNING 2021-02-16 17:06:03,621 log 1928 19116 Not Found: /favicon.ico
WARNING 2021-02-16 17:06:03,621 basehttp 1928 19116 "GET /favicon.ico HTTP/1.1" 404 2196
WARNING 2021-02-16 17:21:56,915 log 1928 2580 Unauthorized: /store/book/
WARNING 2021-02-16 17:21:56,915 basehttp 1928 2580 "GET /store/book/ HTTP/1.1" 401 5090
WARNING 2021-02-16 17:28:42,673 log 22152 5552 Not Found: /
WARNING 2021-02-16 17:28:42,673 basehttp 22152 5552 "GET / HTTP/1.1" 404 2145
WARNING 2021-02-16 18:40:31,241 log 13384 23972 Unauthorized: /store/book/
WARNING 2021-02-16 18:40:31,241 basehttp 13384 23972 "GET /store/book/ HTTP/1.1" 401 5090
WARNING 2021-02-16 18:53:46,499 log 6036 18904 Not Found: /
WARNING 2021-02-16 18:53:46,499 basehttp 6036 18904 "GET / HTTP/1.1" 404 2145
WARNING 2021-02-17 01:34:21,266 log 22164 5312 Unauthorized: /store/book/
WARNING 2021-02-17 01:34:21,267 basehttp 22164 5312 "GET /store/book/ HTTP/1.1" 401 5090
WARNING 2021-02-17 02:08:30,168 log 3460 25460 Unauthorized: /store/user/3/

WARNING 2021-02-17 02:08:30,168 basehttp 3460 25460 "PUT /store/user/3/%0A HTTP/1.1" 401 27
WARNING 2021-02-17 02:09:27,964 log 3460 25460 Unauthorized: /store/user/3/

WARNING 2021-02-17 02:09:27,964 basehttp 3460 25460 "GET /store/user/3/%0A HTTP/1.1" 401 27
WARNING 2021-02-17 02:22:15,104 log 976 20144 Unauthorized: /store/book/
WARNING 2021-02-17 02:22:15,104 basehttp 976 20144 "GET /store/book/ HTTP/1.1" 401 5090
ERROR 2021-02-17 02:37:38,007 log 10628 3320 Internal Server Error: /admin/auth/user/
Traceback (most recent call last):
  File "C:\Users\Abi Blista\AppData\Local\Programs\Python\Python39\lib\site-packages\djongo\sql2mongo\query.py", line 856, in parse
    return handler(self, statement)
  File "C:\Users\Abi Blista\AppData\Local\Programs\Python\Python39\lib\site-packages\djongo\sql2mongo\query.py", line 932, in _select
    return SelectQuery(self.db, self.connection_properties, sm, self._params)
  File "C:\Users\Abi Blista\AppData\Local\Programs\Python\Python39\lib\site-packages\djongo\sql2mongo\query.py", line 116, in __init__
    super().__init__(*args)
  File "C:\Users\Abi Blista\AppData\Local\Programs\Python\Python39\lib\site-packages\djongo\sql2mongo\query.py", line 62, in __init__
    self.parse()
  File "C:\Users\Abi Blista\AppData\Local\Programs\Python\Python39\lib\site-packages\djongo\sql2mongo\query.py", line 152, in parse
    self.where = WhereConverter(self, statement)
  File "C:\Users\Abi Blista\AppData\Local\Programs\Python\Python39\lib\site-packages\djongo\sql2mongo\converters.py", line 27, in __init__
    self.parse()
  File "C:\Users\Abi Blista\AppData\Local\Programs\Python\Python39\lib\site-packages\djongo\sql2mongo\converters.py", line 119, in parse
    self.op = WhereOp(
  File "C:\Users\Abi Blista\AppData\Local\Programs\Python\Python39\lib\site-packages\djongo\sql2mongo\operators.py", line 475, in __init__
    self._statement2ops()
  File "C:\Users\Abi Blista\AppData\Local\Programs\Python\Python39\lib\site-packages\djongo\sql2mongo\operators.py", line 438, in _statement2ops
    if prev_op.lhs is None:
AttributeError: 'NoneType' object has no attribute 'lhs'

The above exception was the direct cause of the following exception:

Traceback (most recent call last):
  File "C:\Users\Abi Blista\AppData\Local\Programs\Python\Python39\lib\site-packages\djongo\cursor.py", line 51, in execute
    self.result = Query(
  File "C:\Users\Abi Blista\AppData\Local\Programs\Python\Python39\lib\site-packages\djongo\sql2mongo\query.py", line 783, in __init__
    self._query = self.parse()
  File "C:\Users\Abi Blista\AppData\Local\Programs\Python\Python39\lib\site-packages\djongo\sql2mongo\query.py", line 884, in parse
    raise exe from e
djongo.exceptions.SQLDecodeError: 

	Keyword: None
	Sub SQL: None
	FAILED SQL: SELECT COUNT(*) AS "__count" FROM "auth_user" WHERE "auth_user"."is_staff"
	Params: ()
	Version: 1.3.3

The above exception was the direct cause of the following exception:

Traceback (most recent call last):
  File "C:\Users\Abi Blista\AppData\Local\Programs\Python\Python39\lib\site-packages\django\db\backends\utils.py", line 84, in _execute
    return self.cursor.execute(sql, params)
  File "C:\Users\Abi Blista\AppData\Local\Programs\Python\Python39\lib\site-packages\djongo\cursor.py", line 59, in execute
    raise db_exe from e
djongo.database.DatabaseError

The above exception was the direct cause of the following exception:

Traceback (most recent call last):
  File "C:\Users\Abi Blista\AppData\Local\Programs\Python\Python39\lib\site-packages\django\core\handlers\exception.py", line 47, in inner
    response = get_response(request)
  File "C:\Users\Abi Blista\AppData\Local\Programs\Python\Python39\lib\site-packages\django\core\handlers\base.py", line 181, in _get_response
    response = wrapped_callback(request, *callback_args, **callback_kwargs)
  File "C:\Users\Abi Blista\AppData\Local\Programs\Python\Python39\lib\site-packages\django\contrib\admin\options.py", line 614, in wrapper
    return self.admin_site.admin_view(view)(*args, **kwargs)
  File "C:\Users\Abi Blista\AppData\Local\Programs\Python\Python39\lib\site-packages\django\utils\decorators.py", line 130, in _wrapped_view
    response = view_func(request, *args, **kwargs)
  File "C:\Users\Abi Blista\AppData\Local\Programs\Python\Python39\lib\site-packages\django\views\decorators\cache.py", line 44, in _wrapped_view_func
    response = view_func(request, *args, **kwargs)
  File "C:\Users\Abi Blista\AppData\Local\Programs\Python\Python39\lib\site-packages\django\contrib\admin\sites.py", line 233, in inner
    return view(request, *args, **kwargs)
  File "C:\Users\Abi Blista\AppData\Local\Programs\Python\Python39\lib\site-packages\django\utils\decorators.py", line 43, in _wrapper
    return bound_method(*args, **kwargs)
  File "C:\Users\Abi Blista\AppData\Local\Programs\Python\Python39\lib\site-packages\django\utils\decorators.py", line 130, in _wrapped_view
    response = view_func(request, *args, **kwargs)
  File "C:\Users\Abi Blista\AppData\Local\Programs\Python\Python39\lib\site-packages\django\contrib\admin\options.py", line 1693, in changelist_view
    cl = self.get_changelist_instance(request)
  File "C:\Users\Abi Blista\AppData\Local\Programs\Python\Python39\lib\site-packages\django\contrib\admin\options.py", line 735, in get_changelist_instance
    return ChangeList(
  File "C:\Users\Abi Blista\AppData\Local\Programs\Python\Python39\lib\site-packages\django\contrib\admin\views\main.py", line 100, in __init__
    self.get_results(request)
  File "C:\Users\Abi Blista\AppData\Local\Programs\Python\Python39\lib\site-packages\django\contrib\admin\views\main.py", line 235, in get_results
    result_count = paginator.count
  File "C:\Users\Abi Blista\AppData\Local\Programs\Python\Python39\lib\site-packages\django\utils\functional.py", line 48, in __get__
    res = instance.__dict__[self.name] = self.func(instance)
  File "C:\Users\Abi Blista\AppData\Local\Programs\Python\Python39\lib\site-packages\django\core\paginator.py", line 94, in count
    return c()
  File "C:\Users\Abi Blista\AppData\Local\Programs\Python\Python39\lib\site-packages\django\db\models\query.py", line 411, in count
    return self.query.get_count(using=self.db)
  File "C:\Users\Abi Blista\AppData\Local\Programs\Python\Python39\lib\site-packages\django\db\models\sql\query.py", line 515, in get_count
    number = obj.get_aggregation(using, ['__count'])['__count']
  File "C:\Users\Abi Blista\AppData\Local\Programs\Python\Python39\lib\site-packages\django\db\models\sql\query.py", line 500, in get_aggregation
    result = compiler.execute_sql(SINGLE)
  File "C:\Users\Abi Blista\AppData\Local\Programs\Python\Python39\lib\site-packages\django\db\models\sql\compiler.py", line 1156, in execute_sql
    cursor.execute(sql, params)
  File "C:\Users\Abi Blista\AppData\Local\Programs\Python\Python39\lib\site-packages\django\db\backends\utils.py", line 98, in execute
    return super().execute(sql, params)
  File "C:\Users\Abi Blista\AppData\Local\Programs\Python\Python39\lib\site-packages\django\db\backends\utils.py", line 66, in execute
    return self._execute_with_wrappers(sql, params, many=False, executor=self._execute)
  File "C:\Users\Abi Blista\AppData\Local\Programs\Python\Python39\lib\site-packages\django\db\backends\utils.py", line 75, in _execute_with_wrappers
    return executor(sql, params, many, context)
  File "C:\Users\Abi Blista\AppData\Local\Programs\Python\Python39\lib\site-packages\django\db\backends\utils.py", line 84, in _execute
    return self.cursor.execute(sql, params)
  File "C:\Users\Abi Blista\AppData\Local\Programs\Python\Python39\lib\site-packages\django\db\utils.py", line 90, in __exit__
    raise dj_exc_value.with_traceback(traceback) from exc_value
  File "C:\Users\Abi Blista\AppData\Local\Programs\Python\Python39\lib\site-packages\django\db\backends\utils.py", line 84, in _execute
    return self.cursor.execute(sql, params)
  File "C:\Users\Abi Blista\AppData\Local\Programs\Python\Python39\lib\site-packages\djongo\cursor.py", line 59, in execute
    raise db_exe from e
django.db.utils.DatabaseError
ERROR 2021-02-17 02:37:38,011 basehttp 10628 3320 "GET /admin/auth/user/?is_staff__exact=1 HTTP/1.1" 500 231251
ERROR 2021-02-17 02:37:45,538 log 10628 3320 Internal Server Error: /admin/auth/user/
Traceback (most recent call last):
  File "C:\Users\Abi Blista\AppData\Local\Programs\Python\Python39\lib\site-packages\djongo\sql2mongo\query.py", line 856, in parse
    return handler(self, statement)
  File "C:\Users\Abi Blista\AppData\Local\Programs\Python\Python39\lib\site-packages\djongo\sql2mongo\query.py", line 932, in _select
    return SelectQuery(self.db, self.connection_properties, sm, self._params)
  File "C:\Users\Abi Blista\AppData\Local\Programs\Python\Python39\lib\site-packages\djongo\sql2mongo\query.py", line 116, in __init__
    super().__init__(*args)
  File "C:\Users\Abi Blista\AppData\Local\Programs\Python\Python39\lib\site-packages\djongo\sql2mongo\query.py", line 62, in __init__
    self.parse()
  File "C:\Users\Abi Blista\AppData\Local\Programs\Python\Python39\lib\site-packages\djongo\sql2mongo\query.py", line 152, in parse
    self.where = WhereConverter(self, statement)
  File "C:\Users\Abi Blista\AppData\Local\Programs\Python\Python39\lib\site-packages\djongo\sql2mongo\converters.py", line 27, in __init__
    self.parse()
  File "C:\Users\Abi Blista\AppData\Local\Programs\Python\Python39\lib\site-packages\djongo\sql2mongo\converters.py", line 119, in parse
    self.op = WhereOp(
  File "C:\Users\Abi Blista\AppData\Local\Programs\Python\Python39\lib\site-packages\djongo\sql2mongo\operators.py", line 476, in __init__
    self.evaluate()
  File "C:\Users\Abi Blista\AppData\Local\Programs\Python\Python39\lib\site-packages\djongo\sql2mongo\operators.py", line 465, in evaluate
    op.evaluate()
  File "C:\Users\Abi Blista\AppData\Local\Programs\Python\Python39\lib\site-packages\djongo\sql2mongo\operators.py", line 258, in evaluate
    self.rhs.negate()
AttributeError: 'NoneType' object has no attribute 'negate'

The above exception was the direct cause of the following exception:

Traceback (most recent call last):
  File "C:\Users\Abi Blista\AppData\Local\Programs\Python\Python39\lib\site-packages\djongo\cursor.py", line 51, in execute
    self.result = Query(
  File "C:\Users\Abi Blista\AppData\Local\Programs\Python\Python39\lib\site-packages\djongo\sql2mongo\query.py", line 783, in __init__
    self._query = self.parse()
  File "C:\Users\Abi Blista\AppData\Local\Programs\Python\Python39\lib\site-packages\djongo\sql2mongo\query.py", line 884, in parse
    raise exe from e
djongo.exceptions.SQLDecodeError: 

	Keyword: None
	Sub SQL: None
	FAILED SQL: SELECT COUNT(*) AS "__count" FROM "auth_user" WHERE NOT "auth_user"."is_superuser"
	Params: ()
	Version: 1.3.3

The above exception was the direct cause of the following exception:

Traceback (most recent call last):
  File "C:\Users\Abi Blista\AppData\Local\Programs\Python\Python39\lib\site-packages\django\db\backends\utils.py", line 84, in _execute
    return self.cursor.execute(sql, params)
  File "C:\Users\Abi Blista\AppData\Local\Programs\Python\Python39\lib\site-packages\djongo\cursor.py", line 59, in execute
    raise db_exe from e
djongo.database.DatabaseError

The above exception was the direct cause of the following exception:

Traceback (most recent call last):
  File "C:\Users\Abi Blista\AppData\Local\Programs\Python\Python39\lib\site-packages\django\core\handlers\exception.py", line 47, in inner
    response = get_response(request)
  File "C:\Users\Abi Blista\AppData\Local\Programs\Python\Python39\lib\site-packages\django\core\handlers\base.py", line 181, in _get_response
    response = wrapped_callback(request, *callback_args, **callback_kwargs)
  File "C:\Users\Abi Blista\AppData\Local\Programs\Python\Python39\lib\site-packages\django\contrib\admin\options.py", line 614, in wrapper
    return self.admin_site.admin_view(view)(*args, **kwargs)
  File "C:\Users\Abi Blista\AppData\Local\Programs\Python\Python39\lib\site-packages\django\utils\decorators.py", line 130, in _wrapped_view
    response = view_func(request, *args, **kwargs)
  File "C:\Users\Abi Blista\AppData\Local\Programs\Python\Python39\lib\site-packages\django\views\decorators\cache.py", line 44, in _wrapped_view_func
    response = view_func(request, *args, **kwargs)
  File "C:\Users\Abi Blista\AppData\Local\Programs\Python\Python39\lib\site-packages\django\contrib\admin\sites.py", line 233, in inner
    return view(request, *args, **kwargs)
  File "C:\Users\Abi Blista\AppData\Local\Programs\Python\Python39\lib\site-packages\django\utils\decorators.py", line 43, in _wrapper
    return bound_method(*args, **kwargs)
  File "C:\Users\Abi Blista\AppData\Local\Programs\Python\Python39\lib\site-packages\django\utils\decorators.py", line 130, in _wrapped_view
    response = view_func(request, *args, **kwargs)
  File "C:\Users\Abi Blista\AppData\Local\Programs\Python\Python39\lib\site-packages\django\contrib\admin\options.py", line 1693, in changelist_view
    cl = self.get_changelist_instance(request)
  File "C:\Users\Abi Blista\AppData\Local\Programs\Python\Python39\lib\site-packages\django\contrib\admin\options.py", line 735, in get_changelist_instance
    return ChangeList(
  File "C:\Users\Abi Blista\AppData\Local\Programs\Python\Python39\lib\site-packages\django\contrib\admin\views\main.py", line 100, in __init__
    self.get_results(request)
  File "C:\Users\Abi Blista\AppData\Local\Programs\Python\Python39\lib\site-packages\django\contrib\admin\views\main.py", line 235, in get_results
    result_count = paginator.count
  File "C:\Users\Abi Blista\AppData\Local\Programs\Python\Python39\lib\site-packages\django\utils\functional.py", line 48, in __get__
    res = instance.__dict__[self.name] = self.func(instance)
  File "C:\Users\Abi Blista\AppData\Local\Programs\Python\Python39\lib\site-packages\django\core\paginator.py", line 94, in count
    return c()
  File "C:\Users\Abi Blista\AppData\Local\Programs\Python\Python39\lib\site-packages\django\db\models\query.py", line 411, in count
    return self.query.get_count(using=self.db)
  File "C:\Users\Abi Blista\AppData\Local\Programs\Python\Python39\lib\site-packages\django\db\models\sql\query.py", line 515, in get_count
    number = obj.get_aggregation(using, ['__count'])['__count']
  File "C:\Users\Abi Blista\AppData\Local\Programs\Python\Python39\lib\site-packages\django\db\models\sql\query.py", line 500, in get_aggregation
    result = compiler.execute_sql(SINGLE)
  File "C:\Users\Abi Blista\AppData\Local\Programs\Python\Python39\lib\site-packages\django\db\models\sql\compiler.py", line 1156, in execute_sql
    cursor.execute(sql, params)
  File "C:\Users\Abi Blista\AppData\Local\Programs\Python\Python39\lib\site-packages\django\db\backends\utils.py", line 98, in execute
    return super().execute(sql, params)
  File "C:\Users\Abi Blista\AppData\Local\Programs\Python\Python39\lib\site-packages\django\db\backends\utils.py", line 66, in execute
    return self._execute_with_wrappers(sql, params, many=False, executor=self._execute)
  File "C:\Users\Abi Blista\AppData\Local\Programs\Python\Python39\lib\site-packages\django\db\backends\utils.py", line 75, in _execute_with_wrappers
    return executor(sql, params, many, context)
  File "C:\Users\Abi Blista\AppData\Local\Programs\Python\Python39\lib\site-packages\django\db\backends\utils.py", line 84, in _execute
    return self.cursor.execute(sql, params)
  File "C:\Users\Abi Blista\AppData\Local\Programs\Python\Python39\lib\site-packages\django\db\utils.py", line 90, in __exit__
    raise dj_exc_value.with_traceback(traceback) from exc_value
  File "C:\Users\Abi Blista\AppData\Local\Programs\Python\Python39\lib\site-packages\django\db\backends\utils.py", line 84, in _execute
    return self.cursor.execute(sql, params)
  File "C:\Users\Abi Blista\AppData\Local\Programs\Python\Python39\lib\site-packages\djongo\cursor.py", line 59, in execute
    raise db_exe from e
django.db.utils.DatabaseError
ERROR 2021-02-17 02:37:45,540 basehttp 10628 3320 "GET /admin/auth/user/?is_superuser__exact=0 HTTP/1.1" 500 234248
WARNING 2021-02-17 03:10:15,110 log 8276 16864 Unauthorized: /store/friend/

WARNING 2021-02-17 03:10:15,111 basehttp 8276 16864 "POST /store/friend/%0A HTTP/1.1" 401 58
WARNING 2021-02-17 03:44:33,348 log 1572 26416 Unauthorized: /store/book/5/

WARNING 2021-02-17 03:44:33,348 basehttp 1572 26416 "GET /store/book/5/%0A HTTP/1.1" 401 27
WARNING 2021-02-17 03:51:01,712 log 8904 25584 Unauthorized: /store/book/

WARNING 2021-02-17 03:51:01,712 basehttp 8904 25584 "POST /store/book/%0A HTTP/1.1" 401 27
WARNING 2021-02-17 03:52:41,056 log 8904 25584 Unauthorized: /store/book/7/

WARNING 2021-02-17 03:52:41,057 basehttp 8904 25584 "GET /store/book/7/%0A HTTP/1.1" 401 27
ERROR 2021-02-17 04:16:48,325 log 24464 3460 Internal Server Error: /store/friend/28/
Traceback (most recent call last):
  File "C:\Users\Abi Blista\AppData\Local\Programs\Python\Python39\lib\site-packages\django\core\handlers\exception.py", line 47, in inner
    response = get_response(request)
  File "C:\Users\Abi Blista\AppData\Local\Programs\Python\Python39\lib\site-packages\django\core\handlers\base.py", line 204, in _get_response
    response = response.render()
  File "C:\Users\Abi Blista\AppData\Local\Programs\Python\Python39\lib\site-packages\django\template\response.py", line 105, in render
    self.content = self.rendered_content
  File "C:\Users\Abi Blista\AppData\Local\Programs\Python\Python39\lib\site-packages\rest_framework\response.py", line 70, in rendered_content
    ret = renderer.render(self.data, accepted_media_type, context)
  File "C:\Users\Abi Blista\AppData\Local\Programs\Python\Python39\lib\site-packages\rest_framework\renderers.py", line 100, in render
    ret = json.dumps(
  File "C:\Users\Abi Blista\AppData\Local\Programs\Python\Python39\lib\site-packages\rest_framework\utils\json.py", line 25, in dumps
    return json.dumps(*args, **kwargs)
  File "C:\Users\Abi Blista\AppData\Local\Programs\Python\Python39\lib\json\__init__.py", line 234, in dumps
    return cls(
  File "C:\Users\Abi Blista\AppData\Local\Programs\Python\Python39\lib\json\encoder.py", line 199, in encode
    chunks = self.iterencode(o, _one_shot=True)
  File "C:\Users\Abi Blista\AppData\Local\Programs\Python\Python39\lib\json\encoder.py", line 257, in iterencode
    return _iterencode(o, 0)
  File "C:\Users\Abi Blista\AppData\Local\Programs\Python\Python39\lib\site-packages\rest_framework\utils\encoders.py", line 67, in default
    return super().default(obj)
  File "C:\Users\Abi Blista\AppData\Local\Programs\Python\Python39\lib\json\encoder.py", line 179, in default
    raise TypeError(f'Object of type {o.__class__.__name__} '
TypeError: Object of type friendlist is not JSON serializable
ERROR 2021-02-17 04:16:48,326 basehttp 24464 3460 "GET /store/friend/28/%0A HTTP/1.1" 500 98960
ERROR 2021-02-17 04:21:42,086 log 12060 22088 Internal Server Error: /store/friendlist/28/
Traceback (most recent call last):
  File "C:\Users\Abi Blista\AppData\Local\Programs\Python\Python39\lib\site-packages\django\core\handlers\exception.py", line 47, in inner
    response = get_response(request)
  File "C:\Users\Abi Blista\AppData\Local\Programs\Python\Python39\lib\site-packages\django\core\handlers\base.py", line 204, in _get_response
    response = response.render()
  File "C:\Users\Abi Blista\AppData\Local\Programs\Python\Python39\lib\site-packages\django\template\response.py", line 105, in render
    self.content = self.rendered_content
  File "C:\Users\Abi Blista\AppData\Local\Programs\Python\Python39\lib\site-packages\rest_framework\response.py", line 70, in rendered_content
    ret = renderer.render(self.data, accepted_media_type, context)
  File "C:\Users\Abi Blista\AppData\Local\Programs\Python\Python39\lib\site-packages\rest_framework\renderers.py", line 100, in render
    ret = json.dumps(
  File "C:\Users\Abi Blista\AppData\Local\Programs\Python\Python39\lib\site-packages\rest_framework\utils\json.py", line 25, in dumps
    return json.dumps(*args, **kwargs)
  File "C:\Users\Abi Blista\AppData\Local\Programs\Python\Python39\lib\json\__init__.py", line 234, in dumps
    return cls(
  File "C:\Users\Abi Blista\AppData\Local\Programs\Python\Python39\lib\json\encoder.py", line 199, in encode
    chunks = self.iterencode(o, _one_shot=True)
  File "C:\Users\Abi Blista\AppData\Local\Programs\Python\Python39\lib\json\encoder.py", line 257, in iterencode
    return _iterencode(o, 0)
  File "C:\Users\Abi Blista\AppData\Local\Programs\Python\Python39\lib\site-packages\rest_framework\utils\encoders.py", line 67, in default
    return super().default(obj)
  File "C:\Users\Abi Blista\AppData\Local\Programs\Python\Python39\lib\json\encoder.py", line 179, in default
    raise TypeError(f'Object of type {o.__class__.__name__} '
TypeError: Object of type friendlist is not JSON serializable
ERROR 2021-02-17 04:21:42,088 basehttp 12060 22088 "GET /store/friendlist/28/ HTTP/1.1" 500 98980
ERROR 2021-02-17 04:22:40,904 log 5760 25192 Internal Server Error: /store/friendlist/28/
Traceback (most recent call last):
  File "C:\Users\Abi Blista\AppData\Local\Programs\Python\Python39\lib\site-packages\django\core\handlers\exception.py", line 47, in inner
    response = get_response(request)
  File "C:\Users\Abi Blista\AppData\Local\Programs\Python\Python39\lib\site-packages\django\core\handlers\base.py", line 204, in _get_response
    response = response.render()
  File "C:\Users\Abi Blista\AppData\Local\Programs\Python\Python39\lib\site-packages\django\template\response.py", line 105, in render
    self.content = self.rendered_content
  File "C:\Users\Abi Blista\AppData\Local\Programs\Python\Python39\lib\site-packages\rest_framework\response.py", line 70, in rendered_content
    ret = renderer.render(self.data, accepted_media_type, context)
  File "C:\Users\Abi Blista\AppData\Local\Programs\Python\Python39\lib\site-packages\rest_framework\renderers.py", line 100, in render
    ret = json.dumps(
  File "C:\Users\Abi Blista\AppData\Local\Programs\Python\Python39\lib\site-packages\rest_framework\utils\json.py", line 25, in dumps
    return json.dumps(*args, **kwargs)
  File "C:\Users\Abi Blista\AppData\Local\Programs\Python\Python39\lib\json\__init__.py", line 234, in dumps
    return cls(
  File "C:\Users\Abi Blista\AppData\Local\Programs\Python\Python39\lib\json\encoder.py", line 199, in encode
    chunks = self.iterencode(o, _one_shot=True)
  File "C:\Users\Abi Blista\AppData\Local\Programs\Python\Python39\lib\json\encoder.py", line 257, in iterencode
    return _iterencode(o, 0)
  File "C:\Users\Abi Blista\AppData\Local\Programs\Python\Python39\lib\site-packages\rest_framework\utils\encoders.py", line 67, in default
    return super().default(obj)
  File "C:\Users\Abi Blista\AppData\Local\Programs\Python\Python39\lib\json\encoder.py", line 179, in default
    raise TypeError(f'Object of type {o.__class__.__name__} '
TypeError: Object of type friendlist is not JSON serializable
ERROR 2021-02-17 04:22:40,906 basehttp 5760 25192 "GET /store/friendlist/28/ HTTP/1.1" 500 98980
ERROR 2021-02-17 04:23:36,417 log 1828 5584 Internal Server Error: /store/friendlist/28/
Traceback (most recent call last):
  File "C:\Users\Abi Blista\AppData\Local\Programs\Python\Python39\lib\site-packages\django\core\handlers\exception.py", line 47, in inner
    response = get_response(request)
  File "C:\Users\Abi Blista\AppData\Local\Programs\Python\Python39\lib\site-packages\django\core\handlers\base.py", line 204, in _get_response
    response = response.render()
  File "C:\Users\Abi Blista\AppData\Local\Programs\Python\Python39\lib\site-packages\django\template\response.py", line 105, in render
    self.content = self.rendered_content
  File "C:\Users\Abi Blista\AppData\Local\Programs\Python\Python39\lib\site-packages\rest_framework\response.py", line 70, in rendered_content
    ret = renderer.render(self.data, accepted_media_type, context)
  File "C:\Users\Abi Blista\AppData\Local\Programs\Python\Python39\lib\site-packages\rest_framework\renderers.py", line 100, in render
    ret = json.dumps(
  File "C:\Users\Abi Blista\AppData\Local\Programs\Python\Python39\lib\site-packages\rest_framework\utils\json.py", line 25, in dumps
    return json.dumps(*args, **kwargs)
  File "C:\Users\Abi Blista\AppData\Local\Programs\Python\Python39\lib\json\__init__.py", line 234, in dumps
    return cls(
  File "C:\Users\Abi Blista\AppData\Local\Programs\Python\Python39\lib\json\encoder.py", line 199, in encode
    chunks = self.iterencode(o, _one_shot=True)
  File "C:\Users\Abi Blista\AppData\Local\Programs\Python\Python39\lib\json\encoder.py", line 257, in iterencode
    return _iterencode(o, 0)
  File "C:\Users\Abi Blista\AppData\Local\Programs\Python\Python39\lib\site-packages\rest_framework\utils\encoders.py", line 67, in default
    return super().default(obj)
  File "C:\Users\Abi Blista\AppData\Local\Programs\Python\Python39\lib\json\encoder.py", line 179, in default
    raise TypeError(f'Object of type {o.__class__.__name__} '
TypeError: Object of type friendlist is not JSON serializable
ERROR 2021-02-17 04:23:36,419 basehttp 1828 5584 "GET /store/friendlist/28/ HTTP/1.1" 500 98980
ERROR 2021-02-17 04:29:51,792 log 23088 9708 Internal Server Error: /store/friendlist/28/
Traceback (most recent call last):
  File "C:\Users\Abi Blista\AppData\Local\Programs\Python\Python39\lib\site-packages\django\core\handlers\exception.py", line 47, in inner
    response = get_response(request)
  File "C:\Users\Abi Blista\AppData\Local\Programs\Python\Python39\lib\site-packages\django\core\handlers\base.py", line 204, in _get_response
    response = response.render()
  File "C:\Users\Abi Blista\AppData\Local\Programs\Python\Python39\lib\site-packages\django\template\response.py", line 105, in render
    self.content = self.rendered_content
  File "C:\Users\Abi Blista\AppData\Local\Programs\Python\Python39\lib\site-packages\rest_framework\response.py", line 70, in rendered_content
    ret = renderer.render(self.data, accepted_media_type, context)
  File "C:\Users\Abi Blista\AppData\Local\Programs\Python\Python39\lib\site-packages\rest_framework\renderers.py", line 100, in render
    ret = json.dumps(
  File "C:\Users\Abi Blista\AppData\Local\Programs\Python\Python39\lib\site-packages\rest_framework\utils\json.py", line 25, in dumps
    return json.dumps(*args, **kwargs)
  File "C:\Users\Abi Blista\AppData\Local\Programs\Python\Python39\lib\json\__init__.py", line 234, in dumps
    return cls(
  File "C:\Users\Abi Blista\AppData\Local\Programs\Python\Python39\lib\json\encoder.py", line 199, in encode
    chunks = self.iterencode(o, _one_shot=True)
  File "C:\Users\Abi Blista\AppData\Local\Programs\Python\Python39\lib\json\encoder.py", line 257, in iterencode
    return _iterencode(o, 0)
  File "C:\Users\Abi Blista\AppData\Local\Programs\Python\Python39\lib\site-packages\rest_framework\utils\encoders.py", line 67, in default
    return super().default(obj)
  File "C:\Users\Abi Blista\AppData\Local\Programs\Python\Python39\lib\json\encoder.py", line 179, in default
    raise TypeError(f'Object of type {o.__class__.__name__} '
TypeError: Object of type friendlist is not JSON serializable
ERROR 2021-02-17 04:29:51,794 basehttp 23088 9708 "GET /store/friendlist/28/ HTTP/1.1" 500 99144
WARNING 2021-02-17 04:38:38,649 log 13024 15216 Not Found: /store/friend/9/
WARNING 2021-02-17 04:38:38,649 basehttp 13024 15216 "PUT /store/friend/9/ HTTP/1.1" 404 3634
WARNING 2021-02-17 15:17:13,927 log 18560 18316 Not Found: /favicon.ico
WARNING 2021-02-17 15:17:13,928 basehttp 18560 18316 "GET /favicon.ico HTTP/1.1" 404 2196
WARNING 2021-02-17 15:31:37,759 log 6776 12340 Not Found: /store/listfriend/
WARNING 2021-02-17 15:31:37,760 basehttp 6776 12340 "GET /store/listfriend/ HTTP/1.1" 404 4379
WARNING 2021-02-17 16:09:54,210 log 11656 12208 Method Not Allowed: /store/txtpost/
WARNING 2021-02-17 16:09:54,213 basehttp 11656 12208 "GET /store/txtpost/ HTTP/1.1" 405 40
WARNING 2021-02-17 16:22:30,262 log 9712 19436 Not Found: /store/friend/11/
WARNING 2021-02-17 16:22:30,263 basehttp 9712 19436 "POST /store/friend/11/ HTTP/1.1" 404 4523
WARNING 2021-02-17 16:22:47,953 log 9712 19436 Not Found: /store/friend/11/
WARNING 2021-02-17 16:22:47,953 basehttp 9712 19436 "PUT /store/friend/11/ HTTP/1.1" 404 4522
WARNING 2021-02-17 16:26:10,474 log 6816 5852 Not Found: /store/friendlist/
WARNING 2021-02-17 16:26:10,475 basehttp 6816 5852 "PUT /store/friendlist/ HTTP/1.1" 404 4525
ERROR 2021-02-17 16:34:40,629 log 5896 6100 Internal Server Error: /store/friendlist/28/
Traceback (most recent call last):
  File "C:\Users\Abi Blista\AppData\Local\Programs\Python\Python39\lib\site-packages\django\core\handlers\exception.py", line 47, in inner
    response = get_response(request)
  File "C:\Users\Abi Blista\AppData\Local\Programs\Python\Python39\lib\site-packages\django\core\handlers\base.py", line 204, in _get_response
    response = response.render()
  File "C:\Users\Abi Blista\AppData\Local\Programs\Python\Python39\lib\site-packages\django\template\response.py", line 105, in render
    self.content = self.rendered_content
  File "C:\Users\Abi Blista\AppData\Local\Programs\Python\Python39\lib\site-packages\rest_framework\response.py", line 70, in rendered_content
    ret = renderer.render(self.data, accepted_media_type, context)
  File "C:\Users\Abi Blista\AppData\Local\Programs\Python\Python39\lib\site-packages\rest_framework\renderers.py", line 100, in render
    ret = json.dumps(
  File "C:\Users\Abi Blista\AppData\Local\Programs\Python\Python39\lib\site-packages\rest_framework\utils\json.py", line 25, in dumps
    return json.dumps(*args, **kwargs)
  File "C:\Users\Abi Blista\AppData\Local\Programs\Python\Python39\lib\json\__init__.py", line 234, in dumps
    return cls(
  File "C:\Users\Abi Blista\AppData\Local\Programs\Python\Python39\lib\json\encoder.py", line 199, in encode
    chunks = self.iterencode(o, _one_shot=True)
  File "C:\Users\Abi Blista\AppData\Local\Programs\Python\Python39\lib\json\encoder.py", line 257, in iterencode
    return _iterencode(o, 0)
  File "C:\Users\Abi Blista\AppData\Local\Programs\Python\Python39\lib\site-packages\rest_framework\utils\encoders.py", line 67, in default
    return super().default(obj)
  File "C:\Users\Abi Blista\AppData\Local\Programs\Python\Python39\lib\json\encoder.py", line 179, in default
    raise TypeError(f'Object of type {o.__class__.__name__} '
TypeError: Object of type friendlist is not JSON serializable
ERROR 2021-02-17 16:34:40,631 basehttp 5896 6100 "GET /store/friendlist/28/ HTTP/1.1" 500 99478
WARNING 2021-02-17 17:01:12,828 log 8220 15812 Not Found: /store/usertype/reader
WARNING 2021-02-17 17:01:12,828 basehttp 8220 15812 "GET /store/usertype/reader HTTP/1.1" 404 4722
WARNING 2021-02-17 17:01:18,103 log 8220 15812 Not Found: /store/usertype/reader/
WARNING 2021-02-17 17:01:18,103 basehttp 8220 15812 "GET /store/usertype/reader/ HTTP/1.1" 404 4725
WARNING 2021-02-17 17:01:47,757 log 8220 15812 Not Found: /store/usertype/
WARNING 2021-02-17 17:01:47,757 basehttp 8220 15812 "GET /store/usertype/?type=reader HTTP/1.1" 404 4716
WARNING 2021-02-17 17:21:38,160 log 3504 10256 Method Not Allowed: /store/usertype/
WARNING 2021-02-17 17:21:38,160 basehttp 3504 10256 "POST /store/usertype/ HTTP/1.1" 405 41
WARNING 2021-02-17 17:31:49,033 log 13076 9612 Not Found: /store/friendprofile/
WARNING 2021-02-17 17:31:49,034 basehttp 13076 9612 "GET /store/friendprofile/?pk=28 HTTP/1.1" 404 4893
WARNING 2021-02-17 17:42:25,737 log 11836 12656 Method Not Allowed: /store/txtpostbyuser/
WARNING 2021-02-17 17:42:25,737 basehttp 11836 12656 "POST /store/txtpostbyuser/?user=28 HTTP/1.1" 405 41
WARNING 2021-02-17 17:54:24,932 log 15944 16760 Method Not Allowed: /store/txtposthomuser/
WARNING 2021-02-17 17:54:24,933 basehttp 15944 16760 "POST /store/txtposthomuser/?pk=28 HTTP/1.1" 405 41
WARNING 2021-02-17 17:57:56,997 log 17016 5360 Not Found: /store/friendlist/
WARNING 2021-02-17 17:57:56,998 basehttp 17016 5360 "GET /store/friendlist/?pk=23 HTTP/1.1" 404 5201
ERROR 2021-02-17 19:56:32,567 log 9556 5848 Internal Server Error: /store/postcomment/
Traceback (most recent call last):
  File "C:\Users\Abi Blista\AppData\Local\Programs\Python\Python39\lib\site-packages\django\core\handlers\exception.py", line 47, in inner
    response = get_response(request)
  File "C:\Users\Abi Blista\AppData\Local\Programs\Python\Python39\lib\site-packages\django\core\handlers\base.py", line 181, in _get_response
    response = wrapped_callback(request, *callback_args, **callback_kwargs)
  File "C:\Users\Abi Blista\AppData\Local\Programs\Python\Python39\lib\site-packages\django\views\decorators\csrf.py", line 54, in wrapped_view
    return view_func(*args, **kwargs)
  File "C:\Users\Abi Blista\AppData\Local\Programs\Python\Python39\lib\site-packages\rest_framework\viewsets.py", line 117, in view
    handler = getattr(self, action)
AttributeError: 'UserVeiwSet' object has no attribute 'create_TXTPostComments'
ERROR 2021-02-17 19:56:32,569 basehttp 9556 5848 "DELETE /store/postcomment/ HTTP/1.1" 500 68573
WARNING 2021-02-17 19:57:24,806 log 3936 1148 Method Not Allowed: /store/postcomment/
WARNING 2021-02-17 19:57:24,806 basehttp 3936 1148 "DELETE /store/postcomment/ HTTP/1.1" 405 43
ERROR 2021-02-17 20:04:35,112 log 4744 19392 Internal Server Error: /store/postcomment/1/
Traceback (most recent call last):
  File "C:\Users\Abi Blista\AppData\Local\Programs\Python\Python39\lib\site-packages\django\core\handlers\exception.py", line 47, in inner
    response = get_response(request)
  File "C:\Users\Abi Blista\AppData\Local\Programs\Python\Python39\lib\site-packages\django\core\handlers\base.py", line 181, in _get_response
    response = wrapped_callback(request, *callback_args, **callback_kwargs)
  File "C:\Users\Abi Blista\AppData\Local\Programs\Python\Python39\lib\site-packages\django\views\decorators\csrf.py", line 54, in wrapped_view
    return view_func(*args, **kwargs)
  File "C:\Users\Abi Blista\AppData\Local\Programs\Python\Python39\lib\site-packages\rest_framework\viewsets.py", line 117, in view
    handler = getattr(self, action)
AttributeError: 'TXTPostCommentsVeiwSet' object has no attribute 'update_User'
ERROR 2021-02-17 20:04:35,113 basehttp 4744 19392 "PUT /store/postcomment/1/ HTTP/1.1" 500 69159
